<?xml version="1.0"?>
<robot name="robot1">

  <link name="world"/>

  <!-- link0 joints -->
  <link name="link0x"/>
  <joint name="joint0x" type="prismatic">
    <axis xyz="1 0 0"/>
    <parent link="world"/>
    <child link="link0x"/>
    <limit effort="10.0" lower="-2" upper="22" velocity="10"/>
  </joint>
  <link name="link0y"/>
  <joint name="joint0y" type="prismatic">
    <axis xyz="0 1 0"/>
    <parent link="link0x"/>
    <child link="link0y"/>
    <limit effort="10.0" lower="-2" upper="2" velocity="1"/>
  </joint>
  <link name="link0z"/>
  <joint name="joint0z" type="prismatic">
    <axis xyz="0 0 1"/>
    <parent link="link0y"/>
    <child link="link0z"/>
    <limit effort="10.0" lower="-5" upper="5" velocity="10"/>
  </joint>
  
  <link name="link0">
    <visual>
      <material name="orange">
        <color rgba="0.8 0.4 0 1"/>
      </material>
      <geometry>
        <sphere radius="0.2"/>
      </geometry>
    </visual>
    <collision>
      <geometry>
        <sphere radius="0.2"/>
      </geometry>
    </collision>
    <inertial>
      <mass value="1.0"/>
	  <inertia ixx="1.0" ixy="0" ixz="0"
			   iyy="1.0" iyz="0"
			   izz="1.0" />
	</inertial>
  </link>
  <joint name="joint0" type="fixed">
    <parent link="link0z"/>
    <child link="link0"/>
  </joint>
  
  <link name="link1">
    <visual>
      <origin xyz="0 0 0"/>
      <material name="green">
        <color rgba="0 1 0 1"/>
      </material>
      <geometry>
        <sphere radius="0.1"/>
      </geometry>
    </visual>
    <visual>
      <origin xyz="0 0 -0.925"/>
      <material name="green">
        <color rgba="0 1 0 1"/>
      </material>
      <geometry>
        <cylinder length="1.85" radius="0.1"/>
      </geometry>
    </visual>
    <visual>
      <origin xyz="0 0 -1.85"/>
      <material name="blue">
        <color rgba="0 0 1 1"/>
      </material>
      <geometry>
        <sphere radius="0.15"/>
      </geometry>
    </visual>
    <collision name="torso">
      <origin xyz="0 0 -0.925"/>
      <geometry>
        <cylinder length="1.85" radius="0.1"/>
      </geometry>
    </collision>
    <collision name="end">
      <origin xyz="0 0 -1.85"/>
      <geometry>
        <sphere radius="0.15"/>
      </geometry>
    </collision>
    <inertial>
      <origin xyz="0 0 -1.85"/>
      <mass value="1.0"/>
	  <inertia ixx="1.0" ixy="0" ixz="0"
			   iyy="1.0" iyz="0"
			   izz="1.0" />
	</inertial>
  </link>
  <joint name="joint1" type="revolute">
    <axis xyz="0 1 0"/>
    <parent link="link0"/>
    <child link="link1"/>
    <limit effort="1.0" lower="-3.14" upper="3.14" velocity="3.14"/>
  </joint>
  <link name="link1_torso"/>
  <joint name="joint1_torso" type="fixed">
    <origin xyz="0 0 -0.925"/>
    <parent link="link1"/>
    <child link ="link1_torso"/>
  </joint>
  <link name="link1_end"/>
  <joint name="joint1_end" type="fixed">
    <origin xyz="0 0 -1.85"/>
    <parent link="link1"/>
    <child link ="link1_end"/>
  </joint>


  <link name="link2">
    <visual>
      <origin xyz="0 0 0"/>
      <material name="red">
        <color rgba="1 0 0 1"/>
      </material>
      <geometry>
        <sphere radius="0.1"/>
      </geometry>
    </visual>
    <visual>
      <origin xyz="0 0 -0.925"/>
      <material name="red">
        <color rgba="1 0 0 1"/>
      </material>
      <geometry>
        <cylinder length="1.85" radius="0.1"/>
      </geometry>
    </visual>
    <visual>
      <origin xyz="0 0 -1.85"/>
      <material name="blue">
        <color rgba="0 0 1 1"/>
      </material>
      <geometry>
        <sphere radius="0.15"/>
      </geometry>
    </visual>
    <collision name="torso">
      <origin xyz="0 0 -0.925"/>
      <geometry>
        <cylinder length="1.85" radius="0.1"/>
      </geometry>
    </collision>
    <collision name="end">
      <origin xyz="0 0 -1.85"/>
      <geometry>
        <sphere radius="0.15"/>
      </geometry>
    </collision>
    <inertial>
      <origin xyz="0 0 -1.85"/>
      <mass value="1.0"/>
	  <inertia ixx="1.0" ixy="0" ixz="0"
			   iyy="1.0" iyz="0"
			   izz="1.0" />
	</inertial>
  </link>
  <joint name="joint2" type="revolute">
    <axis xyz="0 1 0"/>
    <parent link="link0"/>
    <child link="link2"/>
    <limit effort="1.0" lower="-3.14" upper="3.14" velocity="3.14"/>
  </joint>
  <link name="link2_torso"/>
  <joint name="joint2_torso" type="fixed">
    <origin xyz="0 0 -0.925"/>
    <parent link="link2"/>
    <child link ="link2_torso"/>
  </joint>   
  <link name="link2_end"/>
  <joint name="joint2_end" type="fixed">
    <origin xyz="0 0 -1.85"/>
    <parent link="link2"/>
    <child link ="link2_end"/>
  </joint>
  
</robot>
